Workbook

Sheet Genes HOJA
E1: EF | G1: LOXD | Q1: EF | S1: OPR3 | AF1: EF | AG1: ICS | AR1: EF | AT1: MYC2
C2: Sample | D2: Housekeeping gene | E2: Housekeeping gene | F2: Gene of interest | G2: Gene of interest | H2: ΔCt(Ct gene interest - Ct housekeeping gene) | I2: ΔΔCt(ΔCt muestra - ΔCt control average) | J2: 2^-(ΔΔCt) | K2: log | O2: Sample | Q2: Housekeeping gene | S2: Gene of interest | T2: ΔCt(Ct gene interest - Ct housekeeping gene) | U2: ΔΔCt(ΔCt muestra - ΔCt control average) | V2: 2^-(ΔΔCt) | W2: log | AD2: Sample | AE2: Housekeeping gene | AF2: Housekeeping gene | AG2: Gene of interest | AH2: Gene of interest | AI2: ΔCt(Ct gene interest - Ct housekeeping gene) | AJ2: ΔΔCt(ΔCt muestra - ΔCt control average) | AK2: 2^-(ΔΔCt) | AL2: log | AP2: Sample | AQ2: Housekeeping gene | AR2: Housekeeping gene | AS2: Gene of interest | AT2: Gene of interest | AU2: ΔCt(Ct gene interest - Ct housekeeping gene) | AV2: ΔΔCt(ΔCt muestra - ΔCt control average) | AW2: 2^-(ΔΔCt) | AX2: log
B3: C1 2d | C3: 7 | D3: 18.562855 | E3: 17.553822 | F3: 28.257273 | G3: 28.309553 | H3: =(AVERAGE(F3:G3)-AVERAGE(D3:E3)) -> 10.225075 | I3: =H3-$H$52 -> 0.25481606 | J3: =2^-I3 -> 0.83809399 | N3: C1 2d | O3: 7 | P3: 18.562855 | Q3: 17.553822 | R3: 19.769684 | S3: 21.700659 | T3: =(AVERAGE(R3:S3)-AVERAGE(P3:Q3)) -> 2.6768332 | U3: =T3-$T$52 -> -0.75192483 | V3: =2^-U3 -> 1.6840382 | AC3: C1 1d | AD3: 1 | AE3: 21.186722 | AF3: 20.250463 | AG3: 27.545727 | AH3: 28.015465 | AI3: =(AVERAGE(AG3:AH3)-AVERAGE(AE3:AF3)) -> 7.0620031 | AJ3: =AI3-$AG$35 -> 0.32901065 | AK3: =2^-AJ3 -> 0.79608222 | AL3: =LOG(AK3,2) -> -0.32901065 | AO3: C1 7d | AP3: 37 | AQ3: 20.929424 | AR3: 22.087042 | AS3: 27.063175 | AT3: 25.749964 | AU3: =(AVERAGE(AS3:AT3)-AVERAGE(AQ3:AR3)) -> 4.8983364 | AV3: =AU3-$H$55 -> -2.6981684 | AW3: =2^-AV3 -> 6.4897749 | AX3: =LOG(AW3,2) -> 2.6981684
B4: C2 2d | C4: 8 | D4: 17.049051 | E4: 17.679024 | F4: 27.076267 | G4: 26.972845 | H4: =(AVERAGE(F4:G4)-AVERAGE(D4:E4)) -> 9.6605186 | I4: =H4-$H$52 -> -0.30974007 | J4: =2^-I4 -> 1.2394844 | N4: C2 2d | O4: 8 | P4: 17.049051 | Q4: 17.679024 | R4: 21.201502 | S4: 20.481644 | T4: =(AVERAGE(R4:S4)-AVERAGE(P4:Q4)) -> 3.4775352 | U4: =T4-$T$52 -> 0.048777262 | V4: =2^-U4 -> 0.96675534 | AC4: C2 1d | AD4: 2 | AE4: 22.72283 | AF4: 22.412008 | AG4: 29.003445 | AH4: 27.833126 | AI4: =(AVERAGE(AG4:AH4)-AVERAGE(AE4:AF4)) -> 5.8508663 | AJ4: =AI4-$AG$35 -> -0.88212617 | AK4: =2^-AJ4 -> 1.8430896 | AL4: =LOG(AK4,2) -> 0.88212617 | AO4: C2 7d | AP4: 38 | AQ4: 21.836922 | AS4: 25.081184 | AT4: 24.235033 | AU4: =(AVERAGE(AS4:AT4)-AVERAGE(AQ4:AR4)) -> 2.821187 | AV4: =AU4-$H$55 -> -4.7753178 | AW4: =2^-AV4 -> 27.385073 | AX4: =LOG(AW4,2) -> 4.7753178
B5: C3 2d | C5: 9 | E5: 18.180506 | G5: 28.205688 | H5: =(AVERAGE(F5:G5)-AVERAGE(D5:E5)) -> 10.025183 | I5: =H5-$H$52 -> 0.054924011 | J5: =2^-I5 -> 0.96264515 | N5: C3 2d | O5: 9 | P5: 16.207497 | Q5: 18.180506 | R5: 21.847816 | S5: 20.803997 | T5: =(AVERAGE(R5:S5)-AVERAGE(P5:Q5)) -> 4.1319056 | U5: =T5-$T$52 -> 0.70314757 | V5: =2^-U5 -> 0.61423066 | AC5: C3 1d | AD5: 3 | AE5: 20.909298 | AF5: 21.094397 | AG5: 29.036283 | AH5: 27.539627 | AI5: =(AVERAGE(AG5:AH5)-AVERAGE(AE5:AF5)) -> 7.286108 | AJ5: =AI5-$AG$35 -> 0.55311553 | AK5: =2^-AJ5 -> 0.68154673 | AL5: =LOG(AK5,2) -> -0.55311553 | AO5: C3 7d | AP5: 39 | AQ5: 31.127039 | AR5: 30.850796 | AS5: Undetermined | AT5: 36.880978 | AU5: =(AVERAGE(AS5:AT5)-AVERAGE(AQ5:AR5)) -> 5.8920603 | AV5: =AU5-$H$55 -> -1.7044446 | AW5: =2^-AV5 -> 3.2590344 | AX5: =LOG(AW5,2) -> 1.7044446
B6: Bm 1 2d | C6: 10 | D6: 17.392563 | E6: 18.265812 | F6: 25.615421 | G6: 25.747679 | H6: =(AVERAGE(F6:G6)-AVERAGE(D6:E6)) -> 7.8523626 | I6: =H6-$H$52 -> -2.1178961 | J6: =2^-I6 -> 4.3406048 | N6: Bm 1 2d | O6: 10 | P6: 17.392563 | Q6: 18.265812 | R6: 19.664381 | S6: 19.619452 | T6: =(AVERAGE(R6:S6)-AVERAGE(P6:Q6)) -> 1.8127289 | U6: =T6-$T$52 -> -1.6160291 | V6: =2^-U6 -> 3.0653018 | AC6: Bm 1 1d | AD6: 4 | AE6: 21.390375 | AF6: 21.524549 | AG6: 27.416527 | AH6: 27.122839 | AI6: =(AVERAGE(AG6:AH6)-AVERAGE(AE6:AF6)) -> 5.8122206 | AJ6: =AI6-$AG$35 -> -0.92077192 | AK6: =2^-AJ6 -> 1.8931279 | AL6: =LOG(AK6,2) -> 0.92077192 | AO6: Bm 1 7d | AP6: 40 | AQ6: 22.484402 | AR6: 22.659548 | AS6: 27.326216 | AT6: 26.961588 | AU6: =(AVERAGE(AS6:AT6)-AVERAGE(AQ6:AR6)) -> 4.5719271 | AV6: =AU6-$H$55 -> -3.0245778 | AW6: =2^-AV6 -> 8.1374557 | AX6: =LOG(AW6,2) -> 3.0245778
B7: Bm2 2d | C7: 11 | D7: 18.300673 | F7: 28.114885 | G7: 27.348095 | H7: =(AVERAGE(F7:G7)-AVERAGE(D7:E7)) -> 9.4308176 | I7: =H7-$H$52 -> -0.53944111 | J7: =2^-I7 -> 1.4534094 | N7: Bm2 2d | O7: 11 | P7: 18.300673 | Q7: 15.549869 | R7: 20.584335 | S7: 20.793354 | T7: =(AVERAGE(R7:S7)-AVERAGE(P7:Q7)) -> 3.7635741 | U7: =T7-$T$52 -> 0.33481614 | V7: =2^-U7 -> 0.79288518 | AC7: Bm2 1d | AD7: 5 | AE7: 20.659857 | AF7: 20.828537 | AG7: 28.117567 | AH7: 27.720127 | AI7: =(AVERAGE(AG7:AH7)-AVERAGE(AE7:AF7)) -> 7.1746502 | AJ7: =AI7-$AG$35 -> 0.4416577 | AK7: =2^-AJ7 -> 0.7362881 | AL7: =LOG(AK7,2) -> -0.4416577 | AO7: Bm2 7d | AP7: 41 | AQ7: 22.053213 | AR7: 22.400589 | AS7: 25.647228 | AT7: 25.251757 | AU7: =(AVERAGE(AS7:AT7)-AVERAGE(AQ7:AR7)) -> 3.2225914 | AV7: =AU7-$H$55 -> -4.3739134 | AW7: =2^-AV7 -> 20.733812 | AX7: =LOG(AW7,2) -> 4.3739134
B8: Bm 3 2d | C8: 12 | E8: 18.04763 | F8: 29.92415 | G8: 29.333765 | H8: =(AVERAGE(F8:G8)-AVERAGE(D8:E8)) -> 11.581327 | I8: =H8-$H$52 -> 1.6110687 | J8: =2^-I8 -> 0.32735576 | N8: Bm 3 2d | O8: 12 | P8: 16.539883 | Q8: 18.04763 | R8: 19.513596 | S8: 19.164574 | T8: =(AVERAGE(R8:S8)-AVERAGE(P8:Q8)) -> 2.0453281 | U8: =T8-$T$52 -> -1.3834298 | V8: =2^-U8 -> 2.6088787 | AC8: Bm 3 1d | AD8: 6 | AE8: 20.913986 | AF8: 20.40196 | AG8: 27.685566 | AH8: 28.737001 | AI8: =(AVERAGE(AG8:AH8)-AVERAGE(AE8:AF8)) -> 7.5533104 | AJ8: =AI8-$AG$35 -> 0.8203179 | AK8: =2^-AJ8 -> 0.56631714 | AL8: =LOG(AK8,2) -> -0.8203179 | AO8: Bm 3 7d | AP8: 42 | AQ8: 22.666315 | AR8: 21.813253 | AS8: 25.663143 | AT8: 24.849615 | AU8: =(AVERAGE(AS8:AT8)-AVERAGE(AQ8:AR8)) -> 3.0165949 | AV8: =AU8-$H$55 -> -4.57991 | AW8: =2^-AV8 -> 23.916095 | AX8: =LOG(AW8,2) -> 4.57991
B9: C1 3d | C9: 13 | D9: 22.738323 | E9: 21.647028 | G9: 27.195425 | H9: =(AVERAGE(F9:G9)-AVERAGE(D9:E9)) -> 5.0027494 | I9: =H9-$H$53 -> -0.028846741 | J9: =2^-I9 -> 1.0201963 | N9: C1 3d | O9: 13 | P9: 22.738323 | Q9: 21.647028 | R9: 19.567888 | S9: 19.636452 | T9: =(AVERAGE(R9:S9)-AVERAGE(P9:Q9)) -> -2.5905056 | U9: =T9-$T$53 -> -1.2752746 | V9: =2^-U9 -> 2.4204488 | AC9: C1 3d | AD9: 13 | AE9: 22.738323 | AF9: 21.647028 | AG9: 29.119991 | AH9: 26.842112 | AI9: =(AVERAGE(AG9:AH9)-AVERAGE(AE9:AF9)) -> 5.7883759 | AJ9: =AI9-$AG$36 -> -0.31721687 | AK9: =2^-AJ9 -> 1.2459247 | AL9: =LOG(AK9,2) -> 0.31721687 | AO9: C1 8d | AP9: 43 | AQ9: 21.28845 | AR9: 21.822668 | AS9: 25.981977 | AT9: 24.964626 | AU9: =(AVERAGE(AS9:AT9)-AVERAGE(AQ9:AR9)) -> 3.9177427 | AV9: =AU9-$H$57 -> -4.1639102 | AW9: =2^-AV9 -> 17.925112 | AX9: =LOG(AW9,2) -> 4.1639102
B10: C2 3d | C10: 14 | D10: 21.063808 | E10: 19.416796 | F10: 25.147491 | G10: 26.293026 | H10: =(AVERAGE(F10:G10)-AVERAGE(D10:E10)) -> 5.4799566 | I10: =H10-$H$53 -> 0.44836044 | J10: =2^-I10 -> 0.73287525 | N10: C2 3d | O10: 14 | P10: 21.063808 | Q10: 19.416796 | R10: 19.332747 | S10: 19.651995 | T10: =(AVERAGE(R10:S10)-AVERAGE(P10:Q10)) -> -0.74793148 | U10: =T10-$T$53 -> 0.56729952 | V10: =2^-U10 -> 0.67487886 | AC10: C2 3d | AD10: 14 | AE10: 21.063808 | AF10: 19.416796 | AG10: 27.531897 | AH10: 25.885597 | AI10: =(AVERAGE(AG10:AH10)-AVERAGE(AE10:AF10)) -> 6.4684448 | AJ10: =AI10-$AG$36 -> 0.3628521 | AK10: =2^-AJ10 -> 0.77762575 | AL10: =LOG(AK10,2) -> -0.3628521 | AO10: C2 8d | AP10: 44 | AQ10: 20.931124 | AR10: 20.001276 | AS10: 24.728598 | AT10: 24.967602 | AU10: =(AVERAGE(AS10:AT10)-AVERAGE(AQ10:AR10)) -> 4.3818998 | AV10: =AU10-$H$57 -> -3.6997531 | AW10: =2^-AV10 -> 12.993815 | AX10: =LOG(AW10,2) -> 3.6997531
B11: C3 3d | C11: 15 | D11: 20.22966 | E11: 20.15831 | F11: 24.454449 | G11: 25.157686 | H11: =(AVERAGE(F11:G11)-AVERAGE(D11:E11)) -> 4.6120825 | I11: =H11-$H$53 -> -0.4195137 | J11: =2^-I11 -> 1.3374766 | N11: C3 3d | O11: 15 | P11: 20.22966 | Q11: 20.15831 | R11: 19.744747 | S11: 19.428711 | T11: =(AVERAGE(R11:S11)-AVERAGE(P11:Q11)) -> -0.60725594 | U11: =T11-$T$53 -> 0.70797507 | V11: =2^-U11 -> 0.61217877 | AC11: C3 3d | AD11: 15 | AE11: 20.22966 | AF11: 20.15831 | AG11: 26.582962 | AH11: 25.924923 | AI11: =(AVERAGE(AG11:AH11)-AVERAGE(AE11:AF11)) -> 6.0599575 | AJ11: =AI11-$AG$36 -> -0.045635223 | AK11: =2^-AJ11 -> 1.0321375 | AL11: =LOG(AK11,2) -> 0.045635223 | AO11: C3 8d | AP11: 45 | AQ11: 21.440744 | AR11: 22.393072 | AS11: 24.633226 | AT11: 24.73221 | AU11: =(AVERAGE(AS11:AT11)-AVERAGE(AQ11:AR11)) -> 2.76581 | AV11: =AU11-$H$57 -> -5.3158429 | AW11: =2^-AV11 -> 39.831639 | AX11: =LOG(AW11,2) -> 5.3158429
B12: Bm 1 3d | C12: 16 | D12: 18.852619 | E12: 18.145897 | F12: 25.562408 | G12: 25.229315 | H12: =(AVERAGE(F12:G12)-AVERAGE(D12:E12)) -> 6.8966036 | I12: =H12-$H$53 -> 1.8650074 | J12: =2^-I12 -> 0.2745218 | N12: Bm 1 3d | O12: 16 | P12: 18.852619 | Q12: 18.145897 | R12: 18.730783 | S12: 18.329363 | T12: =(AVERAGE(R12:S12)-AVERAGE(P12:Q12)) -> 0.030815125 | U12: =T12-$T$53 -> 1.3460461 | V12: =2^-U12 -> 0.39336864 | AC12: Bm 1 3d | AD12: 16 | AE12: 18.852619 | AF12: 18.145897 | AG12: 25.170755 | AH12: 24.975912 | AI12: =(AVERAGE(AG12:AH12)-AVERAGE(AE12:AF12)) -> 6.5740757 | AJ12: =AI12-$AG$36 -> 0.46848297 | AK12: =2^-AJ12 -> 0.72272416 | AL12: =LOG(AK12,2) -> -0.46848297 | AO12: Bm 1 8d | AP12: 46 | AQ12: 21.8265 | AR12: 21.449644 | AS12: 25.820694 | AT12: 25.47747 | AU12: =(AVERAGE(AS12:AT12)-AVERAGE(AQ12:AR12)) -> 4.0110102 | AV12: =AU12-$H$57 -> -4.0706428 | AW12: =2^-AV12 -> 16.802952 | AX12: =LOG(AW12,2) -> 4.0706428
B13: Bm2 3d | C13: 17 | D13: 21.780043 | E13: 20.533335 | F13: 29.693943 | G13: 27.915049 | H13: =(AVERAGE(F13:G13)-AVERAGE(D13:E13)) -> 7.6478071 | I13: =H13-$H$53 -> 2.6162109 | J13: =2^-I13 -> 0.16309552 | N13: Bm2 3d | O13: 17 | P13: 21.780043 | Q13: 20.533335 | R13: 21.182232 | S13: 20.912151 | T13: =(AVERAGE(R13:S13)-AVERAGE(P13:Q13)) -> -0.10949707 | U13: =T13-$T$53 -> 1.2057339 | V13: =2^-U13 -> 0.43354873 | AC13: Bm2 3d | AD13: 17 | AE13: 21.780043 | AF13: 20.533335 | AG13: 27.996984 | AH13: 28.276325 | AI13: =(AVERAGE(AG13:AH13)-AVERAGE(AE13:AF13)) -> 6.9799662 | AJ13: =AI13-$AG$36 -> 0.87437344 | AK13: =2^-AJ13 -> 0.54549072 | AL13: =LOG(AK13,2) -> -0.87437344 | AO13: Bm2 8d | AP13: 47 | AQ13: 20.932346 | AR13: 21.078363 | AS13: 27.391304 | AT13: 26.17873 | AU13: =(AVERAGE(AS13:AT13)-AVERAGE(AQ13:AR13)) -> 5.7796621 | AV13: =AU13-$H$57 -> -2.3019908 | AW13: =2^-AV13 -> 4.9313779 | AX13: =LOG(AW13,2) -> 2.3019908
B14: Bm 3 3d | C14: 18 | D14: 22.37434 | E14: 21.154541 | F14: 27.96884 | G14: 28.660032 | H14: =(AVERAGE(F14:G14)-AVERAGE(D14:E14)) -> 6.5499954 | I14: =H14-$H$53 -> 1.5183992 | J14: =2^-I14 -> 0.34907302 | N14: Bm 3 3d | O14: 18 | P14: 22.37434 | Q14: 21.154541 | R14: 20.808403 | S14: 21.487812 | T14: =(AVERAGE(R14:S14)-AVERAGE(P14:Q14)) -> -0.61633301 | U14: =T14-$T$53 -> 0.698898 | V14: =2^-U14 -> 0.61604259 | AC14: Bm 3 3d | AD14: 18 | AE14: 22.37434 | AF14: 21.154541 | AG14: 29.282314 | AH14: 27.616253 | AI14: =(AVERAGE(AG14:AH14)-AVERAGE(AE14:AF14)) -> 6.6848431 | AJ14: =AI14-$AG$36 -> 0.57925034 | AK14: =2^-AJ14 -> 0.66931148 | AL14: =LOG(AK14,2) -> -0.57925034 | AO14: Bm 3 8d | AP14: 48 | AQ14: 20.473497 | AR14: 20.24229 | AS14: 25.398392 | AT14: 25.537737 | AU14: =(AVERAGE(AS14:AT14)-AVERAGE(AQ14:AR14)) -> 5.1101704 | AV14: =AU14-$H$57 -> -2.9714826 | AW14: =2^-AV14 -> 7.8434186 | AX14: =LOG(AW14,2) -> 2.9714826
B15: C1 4d | C15: 19 | D15: 17.980774 | E15: 17.505638 | F15: 27.745232 | G15: 26.26825 | H15: =(AVERAGE(F15:G15)-AVERAGE(D15:E15)) -> 9.2635345 | I15: =H15-$H$54 -> 1.0642923 | J15: =2^-I15 -> 0.47820719 | N15: C1 4d | O15: 19 | P15: 17.980774 | Q15: 17.505638 | R15: 21.42804 | S15: 20.940527 | T15: =(AVERAGE(R15:S15)-AVERAGE(P15:Q15)) -> 3.4410772 | U15: =T15-$T$54 -> 0.67002487 | V15: =2^-U15 -> 0.62849585 | AC15: C1 5d | AD15: 25 | AE15: 21.003397 | AF15: 20.653542 | AG15: 26.526417 | AH15: 26.960852 | AI15: =(AVERAGE(AG15:AH15)-AVERAGE(AE15:AF15)) -> 5.9151649 | AJ15: =AI15-$AG$37 -> -0.17626413 | AK15: =2^-AJ15 -> 1.1299541 | AL15: =LOG(AK15,2) -> 0.17626413 | AO15: C1 9d | AP15: 49 | AQ15: 22.816856 | AR15: 22.344206 | AS15: 24.871077 | AT15: 25.215931 | AU15: =(AVERAGE(AS15:AT15)-AVERAGE(AQ15:AR15)) -> 2.4629726 | AV15: =AU15-$H$58 -> 1.1174027 | AW15: =2^-AV15 -> 0.46092288 | AX15: =LOG(AW15,2) -> -1.1174027
B16: C2 4d | C16: 20 | D16: 19.6371 | E16: 17.468639 | F16: 26.41782 | G16: 26.168133 | H16: =(AVERAGE(F16:G16)-AVERAGE(D16:E16)) -> 7.7401066 | I16: =H16-$H$54 -> -0.45913569 | J16: =2^-I16 -> 1.374718 | N16: C2 4d | O16: 20 | P16: 19.6371 | Q16: 17.468639 | R16: 21.311577 | S16: 20.704929 | T16: =(AVERAGE(R16:S16)-AVERAGE(P16:Q16)) -> 2.4553833 | U16: =T16-$T$54 -> -0.31566906 | V16: =2^-U16 -> 1.2445887 | AC16: C2 5d | AD16: 26 | AE16: 19.556295 | AF16: 20.136721 | AG16: 26.34037 | AH16: 26.882698 | AI16: =(AVERAGE(AG16:AH16)-AVERAGE(AE16:AF16)) -> 6.7650261 | AJ16: =AI16-$AG$37 -> 0.67359702 | AK16: =2^-AJ16 -> 0.62694161 | AL16: =LOG(AK16,2) -> -0.67359702 | AO16: C2 9d | AP16: 50 | AQ16: 20.805058 | AR16: 21.153971 | AS16: 25.806185 | AT16: 24.489182 | AU16: =(AVERAGE(AS16:AT16)-AVERAGE(AQ16:AR16)) -> 4.168169 | AV16: =AU16-$H$58 -> 2.8225991 | AW16: =2^-AV16 -> 0.1413556 | AX16: =LOG(AW16,2) -> -2.8225991
B17: C3 4d | C17: 21 | D17: 19.177872 | E17: 19.09478 | F17: 26.379051 | G17: 27.081772 | H17: =(AVERAGE(F17:G17)-AVERAGE(D17:E17)) -> 7.5940857 | I17: =H17-$H$54 -> -0.60515658 | J17: =2^-I17 -> 1.5211438 | N17: C3 4d | O17: 21 | P17: 19.177872 | Q17: 19.09478 | R17: 21.31085 | S17: 21.795195 | T17: =(AVERAGE(R17:S17)-AVERAGE(P17:Q17)) -> 2.4166965 | U17: =T17-$T$54 -> -0.35435581 | V17: =2^-U17 -> 1.2784146 | AC17: C3 5d | AD17: 27 | AE17: 20.998573 | AF17: 20.286203 | AG17: 26.332502 | AH17: 26.140467 | AI17: =(AVERAGE(AG17:AH17)-AVERAGE(AE17:AF17)) -> 5.5940962 | AJ17: =AI17-$AG$37 -> -0.49733289 | AK17: =2^-AJ17 -> 1.4116015 | AL17: =LOG(AK17,2) -> 0.49733289 | AO17: C3 9d | AP17: 51 | AQ17: 21.749001 | AR17: 21.121328 | AS17: 26.659939 | AT17: 24.92141 | AU17: =(AVERAGE(AS17:AT17)-AVERAGE(AQ17:AR17)) -> 4.3555098 | AV17: =AU17-$H$58 -> 3.0099398 | AW17: =2^-AV17 -> 0.12414174 | AX17: =LOG(AW17,2) -> -3.0099398
B18: Bm 1 4d | C18: 22 | D18: 16.797829 | E18: 16.11553 | F18: 26.722025 | H18: =(AVERAGE(F18:G18)-AVERAGE(D18:E18)) -> 10.265346 | I18: =H18-$H$54 -> 2.0661033 | J18: =2^-I18 -> 0.23880363 | N18: Bm 1 4d | O18: 22 | P18: 16.797829 | Q18: 16.11553 | R18: 20.856464 | S18: 21.362583 | T18: =(AVERAGE(R18:S18)-AVERAGE(P18:Q18)) -> 4.6528444 | U18: =T18-$T$54 -> 1.8817921 | V18: =2^-U18 -> 0.27134645 | AC18: Bm 1 5d | AD18: 28 | AE18: 24.936951 | AF18: 22.591633 | AG18: 28.518456 | AH18: 28.63541 | AI18: =(AVERAGE(AG18:AH18)-AVERAGE(AE18:AF18)) -> 4.8126411 | AJ18: =AI18-$AG$37 -> -1.2787879 | AK18: =2^-AJ18 -> 2.4263504 | AL18: =LOG(AK18,2) -> 1.2787879 | AO18: Bm 1 9d | AP18: 52 | AQ18: 21.73633 | AR18: 21.520866 | AS18: 25.4347 | AT18: 25.374287 | AU18: =(AVERAGE(AS18:AT18)-AVERAGE(AQ18:AR18)) -> 3.7758951 | AV18: =AU18-$H$58 -> 2.4303252 | AW18: =2^-AV18 -> 0.18552362 | AX18: =LOG(AW18,2) -> -2.4303252
B19: Bm2 4d | C19: 23 | D19: 17.172258 | E19: 16.408842 | F19: 22.914772 | G19: 25.467049 | H19: =(AVERAGE(F19:G19)-AVERAGE(D19:E19)) -> 7.4003601 | I19: =H19-$H$54 -> -0.79888217 | J19: =2^-I19 -> 1.7397526 | N19: Bm2 4d | O19: 23 | P19: 17.172258 | Q19: 16.408842 | R19: 17.852877 | S19: 18.348011 | T19: =(AVERAGE(R19:S19)-AVERAGE(P19:Q19)) -> 1.3098936 | U19: =T19-$T$54 -> -1.4611588 | V19: =2^-U19 -> 2.7532942 | AC19: Bm2 5d | AD19: 29 | AE19: 19.469219 | AF19: 19.481897 | AG19: 27.76157 | AH19: 27.959574 | AI19: =(AVERAGE(AG19:AH19)-AVERAGE(AE19:AF19)) -> 8.3850136 | AJ19: =AI19-$AG$37 -> 2.2935845 | AK19: =2^-AJ19 -> 0.20396811 | AL19: =LOG(AK19,2) -> -2.2935845 | AO19: Bm2 9d | AP19: 53 | AQ19: 21.967373 | AR19: 21.547497 | AS19: 25.4347 | AU19: =(AVERAGE(AS19:AT19)-AVERAGE(AQ19:AR19)) -> 3.6772652 | AV19: =AU19-$H$58 -> 2.3316952 | AW19: =2^-AV19 -> 0.19865056 | AX19: =LOG(AW19,2) -> -2.3316952
B20: Bm 3 4d | C20: 24 | D20: 18.612457 | E20: 18.1621 | F20: 24.519018 | G20: 27.597687 | H20: =(AVERAGE(F20:G20)-AVERAGE(D20:E20)) -> 7.6710739 | I20: =H20-$H$54 -> -0.52816836 | J20: =2^-I20 -> 1.4420972 | N20: Bm 3 4d | O20: 24 | P20: 18.612457 | Q20: 18.1621 | R20: 20.812447 | S20: 20.232615 | T20: =(AVERAGE(R20:S20)-AVERAGE(P20:Q20)) -> 2.135252 | U20: =T20-$T$54 -> -0.63580036 | V20: =2^-U20 -> 1.5537995 | AC20: Bm 3 5d | AD20: 30 | AE20: 22.262863 | AF20: 21.694347 | AG20: 28.474548 | AH20: 27.829439 | AI20: =(AVERAGE(AG20:AH20)-AVERAGE(AE20:AF20)) -> 6.1733885 | AJ20: =AI20-$AG$37 -> 0.081959407 | AK20: =2^-AJ20 -> 0.94477362 | AL20: =LOG(AK20,2) -> -0.081959407 | AO20: Bm 3 9d | AP20: 54 | AQ20: 21.499489 | AR20: 22.336283 | AS20: 25.4347 | AT20: 23.315838 | AU20: =(AVERAGE(AS20:AT20)-AVERAGE(AQ20:AR20)) -> 2.4573832 | AV20: =AU20-$H$58 -> 1.1118132 | AW20: =2^-AV20 -> 0.46271211 | AX20: =LOG(AW20,2) -> -1.1118132
B21: C1 5d | C21: 25 | D21: 21.003397 | E21: 20.653542 | F21: 28.430086 | G21: 28.078693 | H21: =(AVERAGE(F21:G21)-AVERAGE(D21:E21)) -> 7.4259205 | I21: =H21-$H$55 -> -0.17058436 | J21: =2^-I21 -> 1.1255143 | K21: =LOG(J21,2) -> 0.17058436 | N21: C1 5d | O21: 25 | P21: 21.003397 | Q21: 20.653542 | R21: 25.872694 | S21: 25.804256 | T21: =(AVERAGE(R21:S21)-AVERAGE(P21:Q21)) -> 5.010006 | U21: =T21-$T$55 -> -0.30932649 | V21: =2^-U21 -> 1.2391291 | W21: =LOG(V21,2) -> 0.30932649 | AC21: C1 7d | AD21: 37 | AE21: 20.929424 | AF21: 22.087042 | AG21: 28.712782 | AH21: 28.749775 | AI21: =(AVERAGE(AG21:AH21)-AVERAGE(AE21:AF21)) -> 7.2230453 | AJ21: =AI21-$AG$38 -> 1.519091 | AK21: =2^-AJ21 -> 0.34890569 | AL21: =LOG(AK21,2) -> -1.519091
B22: C2 5d | C22: 26 | D22: 19.556295 | E22: 20.136721 | F22: 28.015543 | G22: 27.906311 | H22: =(AVERAGE(F22:G22)-AVERAGE(D22:E22)) -> 8.114419 | I22: =H22-$H$55 -> 0.51791414 | J22: =2^-I22 -> 0.69838083 | K22: =LOG(J22,2) -> -0.51791414 | N22: C2 5d | O22: 26 | P22: 19.556295 | Q22: 20.136721 | R22: 24.922926 | S22: 25.479542 | T22: =(AVERAGE(R22:S22)-AVERAGE(P22:Q22)) -> 5.3547258 | U22: =T22-$T$55 -> 0.035393397 | V22: =2^-U22 -> 0.97576565 | W22: =LOG(V22,2) -> -0.035393397 | AC22: C2 7d | AD22: 38 | AE22: 21.836922 | AG22: 27.684017 | AH22: 28.156311 | AI22: =(AVERAGE(AG22:AH22)-AVERAGE(AE22:AF22)) -> 6.0832424 | AJ22: =AI22-$AG$38 -> 0.37928804 | AK22: =2^-AJ22 -> 0.7688169 | AL22: =LOG(AK22,2) -> -0.37928804
B23: C3 5d | C23: 27 | D23: 20.998573 | E23: 20.286203 | F23: 27.990288 | G23: 27.792839 | H23: =(AVERAGE(F23:G23)-AVERAGE(D23:E23)) -> 7.2491751 | I23: =H23-$H$55 -> -0.34732978 | J23: =2^-I23 -> 1.2722038 | K23: =LOG(J23,2) -> 0.34732978 | N23: C3 5d | O23: 27 | P23: 20.998573 | Q23: 20.286203 | R23: 26.363192 | S23: 26.108116 | T23: =(AVERAGE(R23:S23)-AVERAGE(P23:Q23)) -> 5.5932655 | U23: =T23-$T$55 -> 0.27393309 | V23: =2^-U23 -> 0.82706172 | W23: =LOG(V23,2) -> -0.27393309 | AC23: C3 7d | AD23: 39 | AE23: 31.127039 | AF23: 30.850796 | AG23: 33.640972 | AH23: 35.948013 | AI23: =(AVERAGE(AG23:AH23)-AVERAGE(AE23:AF23)) -> 3.8055754 | AJ23: =AI23-$AG$38 -> -1.898379 | AK23: =AVERAGE(AK21:AK22) -> 0.5588613 | AL23: =LOG(AK23,2) -> -0.83943783
B24: Bm 1 5d | C24: 28 | E24: 22.591633 | F24: 30.052397 | G24: 29.633871 | H24: =(AVERAGE(F24:G24)-AVERAGE(D24:E24)) -> 7.2515011 | I24: =H24-$H$55 -> -0.34500376 | J24: =2^-I24 -> 1.2701543 | K24: =LOG(J24,2) -> 0.34500376 | N24: Bm 1 5d | O24: 28 | P24: 24.936951 | Q24: 22.591633 | R24: 28.3402 | S24: 29.149803 | T24: =(AVERAGE(R24:S24)-AVERAGE(P24:Q24)) -> 4.98071 | U24: =T24-$T$55 -> -0.33862241 | V24: =2^-U24 -> 1.2645485 | W24: =LOG(V24,2) -> 0.33862241 | AC24: Bm 1 7d | AD24: 40 | AE24: 22.484402 | AF24: 22.659548 | AG24: 29.828554 | AH24: 27.761818 | AI24: =(AVERAGE(AG24:AH24)-AVERAGE(AE24:AF24)) -> 6.2232113 | AJ24: =AI24-$AG$38 -> 0.51925691 | AK24: =2^-AJ24 -> 0.69773112 | AL24: =LOG(AK24,2) -> -0.51925691
B25: Bm2 5d | C25: 29 | D25: 19.469219 | E25: 19.481897 | F25: 27.80266 | G25: 27.112232 | H25: =(AVERAGE(F25:G25)-AVERAGE(D25:E25)) -> 7.9818878 | I25: =H25-$H$55 -> 0.38538297 | J25: =2^-I25 -> 0.76557575 | K25: =LOG(J25,2) -> -0.38538297 | N25: Bm2 5d | O25: 29 | P25: 19.469219 | Q25: 19.481897 | R25: 25.755611 | S25: 27.77602 | T25: =(AVERAGE(R25:S25)-AVERAGE(P25:Q25)) -> 7.2902575 | U25: =T25-$T$55 -> 1.970925 | V25: =2^-U25 -> 0.25508942 | W25: =LOG(V25,2) -> -1.970925 | AC25: Bm2 7d | AD25: 41 | AE25: 22.053213 | AF25: 22.400589 | AG25: 28.315805 | AH25: 27.887474 | AI25: =(AVERAGE(AG25:AH25)-AVERAGE(AE25:AF25)) -> 5.8747387 | AJ25: =AI25-$AG$38 -> 0.17078431 | AK25: =2^-AJ25 -> 0.8883596 | AL25: =LOG(AK25,2) -> -0.17078431 | AT25: 5d | AU25: =AVERAGE(AU3:AU5) -> 4.5371946
B26: Bm 3 5d | C26: 30 | D26: 22.262863 | E26: 21.694347 | F26: =AVERAGE(F24:F25) -> 28.927528 | G26: =AVERAGE(G24:G25) -> 28.373052 | H26: =(AVERAGE(F26:G26)-AVERAGE(D26:E26)) -> 6.6716847 | I26: =H26-$H$55 -> -0.92482011 | J26: =2^-I26 -> 1.8984475 | K26: =LOG(J26,2) -> 0.92482011 | N26: Bm 3 5d | O26: 30 | P26: 22.262863 | Q26: 21.694347 | R26: 28.626881 | S26: 28.719343 | T26: =(AVERAGE(R26:S26)-AVERAGE(P26:Q26)) -> 6.6945066 | U26: =T26-$T$55 -> 1.3751742 | V26: =2^-U26 -> 0.38550615 | W26: =LOG(V26,2) -> -1.3751742 | AC26: Bm 3 7d | AD26: 42 | AE26: 22.666315 | AF26: 21.813253 | AG26: 27.418608 | AH26: =AVERAGE(AG25:AH25) -> 28.10164 | AI26: =(AVERAGE(AG26:AH26)-AVERAGE(AE26:AF26)) -> 5.5203395 | AJ26: =AI26-$AG$38 -> -0.18361489 | AK26: =2^-AJ26 -> 1.1357261 | AL26: =LOG(AK26,2) -> 0.18361489 | AT26: 7d | AU26: =AVERAGE(AU9:AU11) -> 3.6884842
B27: C1 6d | C27: 31 | D27: 17.807966 | E27: 17.894079 | F27: 29.313189 | G27: 28.990728 | H27: =(AVERAGE(F27:G27)-AVERAGE(D27:E27)) -> 11.300936 | I27: =H27-$H$56 -> 0.73332405 | J27: =2^-I27 -> 0.60151639 | N27: C1 6d | O27: 31 | P27: 17.807966 | Q27: 17.894079 | R27: 20.822639 | S27: 20.710474 | T27: =(AVERAGE(R27:S27)-AVERAGE(P27:Q27)) -> 2.915534 | U27: =T27-$T$56 -> 0.51237456 | V27: =2^-U27 -> 0.70106759 | AC27: C1 9d | AD27: 49 | AE27: 22.816856 | AF27: 22.344206 | AG27: 27.895035 | AH27: 27.141615 | AI27: =(AVERAGE(AG27:AH27)-AVERAGE(AE27:AF27)) -> 4.9377937 | AJ27: =AI27-$AG$39 -> -0.59529114 | AK27: =2^-AJ27 -> 1.5107774 | AL27: =LOG(AK27,2) -> 0.59529114 | AT27: 10d | AU27: =AVERAGE(AU15:AU17) -> 3.6622171
B28: C2 6d | C28: 32 | D28: 18.269285 | E28: 16.487997 | G28: 27.835989 | H28: =(AVERAGE(F28:G28)-AVERAGE(D28:E28)) -> 10.457348 | I28: =H28-$H$56 -> -0.11026382 | J28: =2^-I28 -> 1.0794256 | N28: C2 6d | O28: 32 | P28: 18.269285 | Q28: 16.487997 | R28: 19.944881 | S28: 19.756725 | T28: =(AVERAGE(R28:S28)-AVERAGE(P28:Q28)) -> 2.4721622 | U28: =T28-$T$56 -> 0.069002787 | V28: =2^-U28 -> 0.9532967 | AC28: C2 9d | AD28: 50 | AE28: 20.805058 | AF28: 21.153971 | AG28: 27.482225 | AH28: 27.300201 | AI28: =(AVERAGE(AG28:AH28)-AVERAGE(AE28:AF28)) -> 6.4116993 | AJ28: =AI28-$AG$39 -> 0.87861443 | AK28: =2^-AJ28 -> 0.54388954 | AL28: =LOG(AK28,2) -> -0.87861443
B29: C3 6d | C29: 33 | D29: 19.378029 | E29: 18.377132 | F29: 28.126972 | G29: 29.517292 | H29: =(AVERAGE(F29:G29)-AVERAGE(D29:E29)) -> 9.9445515 | I29: =H29-$H$56 -> -0.62306023 | J29: =2^-I29 -> 1.5401386 | N29: C3 6d | O29: 33 | P29: 19.378029 | Q29: 18.377132 | R29: 21.453163 | S29: 19.945562 | T29: =(AVERAGE(R29:S29)-AVERAGE(P29:Q29)) -> 1.8217821 | U29: =T29-$T$56 -> -0.58137735 | V29: =2^-U29 -> 1.4962771 | AC29: C3 9d | AD29: 51 | AE29: 21.749001 | AF29: 21.121328 | AG29: 26.816687 | AH29: 26.553165 | AI29: =(AVERAGE(AG29:AH29)-AVERAGE(AE29:AF29)) -> 5.2497616 | AJ29: =AI29-$AG$39 -> -0.28332329 | AK29: =2^-AJ29 -> 1.216995 | AL29: =LOG(AK29,2) -> 0.28332329 | AP29: C | AQ29: Error | AR29: Bm | AS29: Error
B30: Bm 1 6d | C30: 34 | D30: 16.629742 | E30: 14.34235 | F30: 26.632624 | H30: =(AVERAGE(F30:G30)-AVERAGE(D30:E30)) -> 11.146578 | I30: =H30-$H$56 -> 0.57896614 | J30: =2^-I30 -> 0.66944334 | N30: Bm 1 6d | O30: 34 | P30: 16.629742 | Q30: 14.34235 | R30: 19.2244 | S30: 19.603775 | T30: =(AVERAGE(R30:S30)-AVERAGE(P30:Q30)) -> 3.9280415 | U30: =T30-$T$56 -> 1.524882 | V30: =2^-U30 -> 0.34750798 | AC30: Bm 1 9d | AD30: 52 | AE30: 21.73633 | AF30: 21.520866 | AG30: 27.075428 | AH30: 27.21867 | AI30: =(AVERAGE(AG30:AH30)-AVERAGE(AE30:AF30)) -> 5.5184507 | AJ30: =AI30-$AG$39 -> -0.014634132 | AK30: =2^-AJ30 -> 1.0101952 | AL30: =LOG(AK30,2) -> 0.014634132 | AO30: 7d | AP30: =AVERAGE(AW3:AW5) -> 12.377961 | AQ30: =_xlfn.STDEV.S(AW3:AW5)/SQRT(3) -> 7.5612937 | AR30: =AVERAGE(AW6:AW8) -> 17.595787 | AS30: =_xlfn.STDEV.S(AW6:AW8)/SQRT(3) -> 4.8175638
B31: Bm2 6d | C31: 35 | D31: 19.288746 | E31: 18.920383 | F31: 28.197559 | G31: 28.608381 | H31: =(AVERAGE(F31:G31)-AVERAGE(D31:E31)) -> 9.2984056 | I31: =H31-$H$56 -> -1.269206 | J31: =2^-I31 -> 2.4102888 | N31: Bm2 6d | O31: 35 | P31: 19.288746 | Q31: 18.920383 | R31: 20.783791 | S31: 20.59255 | T31: =(AVERAGE(R31:S31)-AVERAGE(P31:Q31)) -> 1.5836058 | U31: =T31-$T$56 -> -0.81955369 | V31: =2^-U31 -> 1.7648599 | AC31: Bm2 9d | AD31: 53 | AE31: 21.967373 | AF31: 21.547497 | AG31: 26.602541 | AH31: 26.820648 | AI31: =(AVERAGE(AG31:AH31)-AVERAGE(AE31:AF31)) -> 4.9541597 | AJ31: =AI31-$AG$39 -> -0.57892513 | AK31: =2^-AJ31 -> 1.4937359 | AL31: =LOG(AK31,2) -> 0.57892513 | AO31: 8d | AP31: =AVERAGE(AW9:AW11) -> 23.583522 | AQ31: =_xlfn.STDEV.S(AW9:AW11)/SQRT(3) -> 8.2478363 | AR31: =AVERAGE(AW12:AW14) -> 9.8592494 | AS31: =_xlfn.STDEV.S(AW12:AW14)/SQRT(3) -> 3.5721724
B32: Bm 3 6d | C32: 36 | D32: 17.951269 | E32: 15.451588 | F32: 26.734798 | G32: 27.995167 | H32: =(AVERAGE(F32:G32)-AVERAGE(D32:E32)) -> 10.663554 | I32: =H32-$H$56 -> 0.095942497 | J32: =2^-I32 -> 0.93566079 | N32: Bm 3 6d | O32: 36 | P32: 17.951269 | Q32: 15.451588 | R32: 20.501608 | S32: 20.836742 | T32: =(AVERAGE(R32:S32)-AVERAGE(P32:Q32)) -> 3.9677467 | U32: =T32-$T$56 -> 1.5645873 | V32: =2^-U32 -> 0.33807441 | AC32: Bm 3 9d | AD32: 54 | AE32: 21.499489 | AF32: 22.336283 | AG32: 26.54211 | AH32: 26.607286 | AI32: =(AVERAGE(AG32:AH32)-AVERAGE(AE32:AF32)) -> 4.6568127 | AJ32: =AI32-$AG$39 -> -0.8762722 | AK32: =2^-AJ32 -> 1.8356261 | AL32: =LOG(AK32,2) -> 0.8762722 | AO32: 9d | AP32: =AVERAGE(AW15:AW17) -> 0.24214007 | AQ32: =_xlfn.STDEV.S(AW15:AW17)/SQRT(3) -> 0.10950421 | AR32: =AVERAGE(AW18:AW20) -> 0.28229543 | AS32: =_xlfn.STDEV.S(AW18:AW20)/SQRT(3) -> 0.090287897
B33: C1 7d | C33: 37 | D33: 20.929424 | E33: 22.087042 | F33: 30.311625 | G33: 30.221291 | H33: =(AVERAGE(F33:G33)-AVERAGE(D33:E33)) -> 8.7582245 | I33: =H33-$H$57 -> 0.67657153 | J33: =2^-I33 -> 0.62565033 | K33: =LOG(J33,2) -> -0.67657153 | N33: C1 7d | O33: 37 | P33: 20.929424 | Q33: 22.087042 | R33: 27.530617 | S33: 26.812742 | T33: =(AVERAGE(R33:S33)-AVERAGE(P33:Q33)) -> 5.6634464 | U33: =T33-$T$57 -> 1.7410145 | V33: =2^-U33 -> 0.29915924 | W33: =LOG(V33,2) -> -1.7410145
B34: C2 7d | C34: 38 | D34: 21.836922 | E34: =AVERAGE(D33:D34) -> 21.383173 | F34: 28.986437 | G34: 28.925531 | H34: =(AVERAGE(F34:G34)-AVERAGE(D34:E34)) -> 7.3459368 | I34: =H34-$H$57 -> -0.73571618 | J34: =2^-I34 -> 1.6652239 | K34: =LOG(J34,2) -> 0.73571618 | N34: C2 7d | O34: 38 | P34: 21.836922 | R34: 26.44907 | S34: 25.900293 | T34: =(AVERAGE(R34:S34)-AVERAGE(P34:Q34)) -> 4.33776 | U34: =T34-$T$57 -> 0.41532803 | V34: =2^-U34 -> 0.74984898 | W34: =LOG(V34,2) -> -0.41532803
B35: C3 7d | C35: 39 | D35: =AVERAGE(D33:E33) -> 21.508233 | F35: =AVERAGE(F33:F34) -> 29.649031 | H35: =(AVERAGE(F35:G35)-AVERAGE(D35:E35)) -> 8.1407976 | I35: =H35-$H$57 -> 0.059144656 | J35: =2^-I35 -> 0.95983302 | K35: =LOG(J35,2) -> -0.059144656 | N35: C3 7d | O35: 39 | P35: 31.127039 | Q35: 30.850796 | R35: 32.638004 | S35: 32.872009 | T35: =(AVERAGE(R35:S35)-AVERAGE(P35:Q35)) -> 1.7660894 | U35: =T35-$T$57 -> -2.1563425 | V35: =AVERAGE(V33:V34) -> 0.52450411 | W35: =LOG(V35,2) -> -0.93097402 | AF35: 1d | AG35: =AVERAGE(AI3:AI5) -> 6.7329925
B36: Bm 1 7d | C36: 40 | D36: 22.484402 | E36: 22.659548 | F36: 30.039825 | G36: 30.180965 | H36: =(AVERAGE(F36:G36)-AVERAGE(D36:E36)) -> 7.5384207 | I36: =H36-$H$57 -> -0.54323228 | J36: =2^-I36 -> 1.4572337 | K36: =LOG(J36,2) -> 0.54323228 | N36: Bm 1 7d | O36: 40 | P36: 22.484402 | Q36: 22.659548 | R36: 26.208107 | S36: 26.198566 | T36: =(AVERAGE(R36:S36)-AVERAGE(P36:Q36)) -> 3.631362 | U36: =T36-$T$57 -> -0.29106998 | V36: =2^-U36 -> 1.2235474 | W36: =LOG(V36,2) -> 0.29106998 | AF36: 3d | AG36: =AVERAGE(AI9:AI11) -> 6.1055927
B37: Bm2 7d | C37: 41 | D37: 22.053213 | E37: 22.400589 | F37: 29.964874 | G37: 28.933453 | H37: =(AVERAGE(F37:G37)-AVERAGE(D37:E37)) -> 7.2222624 | I37: =H37-$H$57 -> -0.85939058 | J37: =2^-I37 -> 1.8142718 | K37: =LOG(J37,2) -> 0.85939058 | N37: Bm2 7d | O37: 41 | P37: 22.053213 | Q37: 22.400589 | R37: 28.036987 | S37: 27.172014 | T37: =(AVERAGE(R37:S37)-AVERAGE(P37:Q37)) -> 5.3775997 | U37: =T37-$T$57 -> 1.4551678 | V37: =2^-U37 -> 0.36471267 | W37: =LOG(V37,2) -> -1.4551678 | AF37: 5d | AG37: =AVERAGE(AI15:AI17) -> 6.0914291
B38: Bm 3 7d | C38: 42 | D38: 22.666315 | E38: 21.813253 | F38: =AVERAGE(G36:G37) -> 29.557209 | H38: =(AVERAGE(F38:G38)-AVERAGE(D38:E38)) -> 7.3174248 | I38: =H38-$H$57 -> -0.76422819 | J38: =2^-I38 -> 1.6984611 | K38: =LOG(J38,2) -> 0.76422819 | N38: Bm 3 7d | O38: 42 | P38: 22.666315 | Q38: 21.813253 | R38: 24.569788 | S38: 24.791063 | T38: =(AVERAGE(R38:S38)-AVERAGE(P38:Q38)) -> 2.4406414 | U38: =T38-$T$57 -> -1.4817905 | V38: =2^-U38 -> 2.7929515 | W38: =LOG(V38,2) -> 1.4817905 | AF38: 7d | AG38: =AVERAGE(AI21:AI23) -> 5.7039544
B39: C1 8d | C39: 43 | D39: 21.28845 | E39: 21.822668 | F39: 22.864216 | G39: 22.431517 | H39: =(AVERAGE(F39:G39)-AVERAGE(D39:E39)) -> 1.0923071 | I39: =H39-$H$58 -> -0.25326284 | J39: =2^-I39 -> 1.1918997 | K39: =LOG(J39,2) -> 0.25326284 | N39: C1 8d | O39: 43 | P39: 21.28845 | Q39: 21.822668 | R39: 26.138163 | S39: 25.741388 | T39: =(AVERAGE(R39:S39)-AVERAGE(P39:Q39)) -> 4.3842163 | U39: =T39-$T$58 -> -0.4118309 | V39: =2^-U39 -> 1.3303731 | W39: =LOG(V39,2) -> 0.4118309 | AF39: 10d | AG39: =AVERAGE(AI27:AI29) -> 5.5330849
B40: C2 8d | C40: 44 | D40: 20.931124 | E40: 20.001276 | F40: 21.227573 | G40: 21.417307 | H40: =(AVERAGE(F40:G40)-AVERAGE(D40:E40)) -> 0.85624027 | I40: =H40-$H$58 -> -0.48932966 | J40: =2^-I40 -> 1.4037925 | K40: =LOG(J40,2) -> 0.48932966 | N40: C2 8d | O40: 44 | P40: 20.931124 | Q40: 20.001276 | R40: 26.622063 | S40: 24.979567 | T40: =(AVERAGE(R40:S40)-AVERAGE(P40:Q40)) -> 5.3346148 | U40: =T40-$T$58 -> 0.53856754 | V40: =2^-U40 -> 0.68845414 | W40: =LOG(V40,2) -> -0.53856754 | AD40: C | AE40: Error | AF40: Bm | AG40: Error
...

Sheet Genes hoja norm ambos const
D2: UBIQ | F2: EF | H2: LOXD | R2: UBIQ | T2: EF | V2: OPR3 | AF2: UBIQ | AH2: EF | AJ2: ICS
C3: Sample | F3: Housekeeping gene | G3: Housekeeping gene | H3: Gene of interest | I3: Gene of interest | J3: ΔCt(Ct gene interest - Ct housekeeping gene) | K3: ΔΔCt(ΔCt muestra - ΔCt control average) | L3: 2^-(ΔΔCt) | Q3: Sample | R3: Housekeeping gene | V3: Gene of interest | X3: ΔCt(Ct gene interest - Ct housekeeping gene) | Y3: ΔΔCt(ΔCt muestra - ΔCt control average) | Z3: 2^-(ΔΔCt) | AE3: Sample | AF3: Housekeeping gene | AJ3: Gene of interest | AL3: ΔCt(Ct gene interest - Ct housekeeping gene) | AM3: ΔΔCt(ΔCt muestra - ΔCt control average) | AN3: 2^-(ΔΔCt)
B4: C1 2d | C4: 7 | D4: 20.584412 | E4: 20.713362 | F4: 18.562855 | G4: 17.553822 | H4: 28.257273 | I4: 28.309553 | J4: =(AVERAGE(H4:I4)-AVERAGE(D4:G4)) -> 8.9298005 | K4: =J4-$J$53 -> 1.2833219 | L4: =2^-K4 -> 0.41084841 | P4: C1 2d | Q4: 7 | R4: 20.584412 | S4: 20.713362 | T4: 18.562855 | U4: 17.553822 | V4: 19.769684 | W4: 21.700659 | X4: =(AVERAGE(V4:W4)-AVERAGE(R4:U4)) -> 1.3815589 | Y4: =X4-$X$53 -> 0.16522948 | Z4: =2^-Y4 -> 0.89178666 | AD4: C1 1d | AE4: 1 | AF4: 24.554674 | AG4: 23.712543 | AH4: 21.186722 | AI4: 20.250463 | AJ4: 27.545727 | AK4: 28.015465 | AL4: =(AVERAGE(AJ4:AK4)-AVERAGE(AF4:AI4)) -> 5.354495 | AM4: =AL4-$AJ$36 -> -0.039046446 | AN4: =2^-AM4 -> 1.0274345
B5: C2 2d | C5: 8 | D5: 22.17337 | E5: 22.022058 | F5: 17.049051 | G5: 17.679024 | H5: 27.076267 | I5: 26.972845 | J5: =(AVERAGE(H5:I5)-AVERAGE(D5:G5)) -> 7.2936802 | K5: =J5-$J$53 -> -0.35279841 | L5: =2^-K5 -> 1.2770353 | P5: C2 2d | Q5: 8 | R5: 22.17337 | S5: 22.022058 | T5: 17.049051 | U5: 17.679024 | V5: 21.201502 | W5: 20.481644 | X5: =(AVERAGE(V5:W5)-AVERAGE(R5:U5)) -> 1.1106968 | Y5: =X5-$X$53 -> -0.10563262 | Z5: =2^-Y5 -> 1.0759661 | AD5: C2 1d | AE5: 2 | AF5: 23.811571 | AG5: 24.252682 | AH5: 22.72283 | AI5: 22.412008 | AJ5: 29.003445 | AK5: 27.833126 | AL5: =(AVERAGE(AJ5:AK5)-AVERAGE(AF5:AI5)) -> 5.1185126 | AM5: =AL5-$AJ$36 -> -0.27502886 | AN5: =2^-AM5 -> 1.2100183
B6: C3 2d | C6: 9 | D6: 23.045595 | E6: 23.243099 | G6: 18.180506 | I6: 28.205688 | J6: =(AVERAGE(H6:I6)-AVERAGE(D6:G6)) -> 6.7159551 | K6: =J6-$J$53 -> -0.9305235 | L6: =2^-K6 -> 1.9059675 | P6: C3 2d | Q6: 9 | R6: 23.045595 | S6: 23.243099 | T6: 16.207497 | U6: 18.180506 | V6: 21.847816 | W6: 20.803997 | X6: =(AVERAGE(V6:W6)-AVERAGE(R6:U6)) -> 1.1567326 | Y6: =X6-$X$53 -> -0.059596856 | Z6: =2^-Y6 -> 1.0421745 | AD6: C3 1d | AE6: 3 | AF6: 24.243973 | AG6: 24.073687 | AH6: 20.909298 | AI6: 21.094397 | AJ6: 29.036283 | AK6: 27.539627 | AL6: =(AVERAGE(AJ6:AK6)-AVERAGE(AF6:AI6)) -> 5.7076168 | AM6: =AL6-$AJ$36 -> 0.31407531 | AN6: =2^-AM6 -> 0.80436638
B7: Bm 1 2d | C7: 10 | D7: 21.155014 | E7: 21.247477 | F7: 17.392563 | G7: 18.265812 | H7: 25.615421 | I7: 25.747679 | J7: =(AVERAGE(H7:I7)-AVERAGE(D7:G7)) -> 6.1663337 | K7: =J7-$J$53 -> -1.4801449 | L7: =2^-K7 -> 2.7897676 | P7: Bm 1 2d | Q7: 10 | R7: 21.155014 | S7: 21.247477 | T7: 17.392563 | U7: 18.265812 | V7: 19.664381 | W7: 19.619452 | X7: =(AVERAGE(V7:W7)-AVERAGE(R7:U7)) -> 0.12669992 | Y7: =X7-$X$53 -> -1.0896295 | Z7: =2^-Y7 -> 2.1281937 | AD7: Bm 1 1d | AE7: 4 | AF7: 24.691946 | AG7: 23.844992 | AH7: 21.390375 | AI7: 21.524549 | AJ7: 27.416527 | AK7: 27.122839 | AL7: =(AVERAGE(AJ7:AK7)-AVERAGE(AF7:AI7)) -> 4.4067173 | AM7: =AL7-$AJ$36 -> -0.98682419 | AN7: =2^-AM7 -> 1.9818176
B8: Bm2 2d | C8: 11 | D8: 22.501272 | E8: 22.638418 | F8: 18.300673 | H8: 28.114885 | I8: 27.348095 | J8: =(AVERAGE(H8:I8)-AVERAGE(D8:G8)) -> 6.5847025 | K8: =J8-$J$53 -> -1.0617761 | L8: =2^-K8 -> 2.0874999 | P8: Bm2 2d | Q8: 11 | R8: 22.501272 | S8: 22.638418 | T8: 18.300673 | U8: 15.549869 | V8: 20.584335 | W8: 20.793354 | X8: =(AVERAGE(V8:W8)-AVERAGE(R8:U8)) -> 0.9412868 | Y8: =X8-$X$53 -> -0.27504261 | Z8: =2^-Y8 -> 1.2100298 | AD8: Bm2 1d | AE8: 5 | AF8: 24.913391 | AG8: 24.346113 | AH8: 20.659857 | AI8: 20.828537 | AJ8: 28.117567 | AK8: 27.720127 | AL8: =(AVERAGE(AJ8:AK8)-AVERAGE(AF8:AI8)) -> 5.2318726 | AM8: =AL8-$AJ$36 -> -0.16166894 | AN8: =2^-AM8 -> 1.1185804
B9: Bm 3 2d | C9: 12 | D9: 21.447052 | E9: 21.29052 | G9: 18.04763 | H9: 29.92415 | I9: 29.333765 | J9: =(AVERAGE(H9:I9)-AVERAGE(D9:G9)) -> 9.3672237 | K9: =J9-$J$53 -> 1.7207451 | L9: =2^-K9 -> 0.30339198 | P9: Bm 3 2d | Q9: 12 | R9: 21.447052 | S9: 21.29052 | T9: 16.539883 | U9: 18.04763 | V9: 19.513596 | W9: 19.164574 | X9: =(AVERAGE(V9:W9)-AVERAGE(R9:U9)) -> 0.0078134537 | Y9: =X9-$X$53 -> -1.208516 | Z9: =2^-Y9 -> 2.3109979 | AD9: Bm 3 1d | AE9: 6 | AF9: 23.177378 | AG9: 24.465054 | AH9: 20.913986 | AI9: 20.40196 | AJ9: 27.685566 | AK9: 28.737001 | AL9: =(AVERAGE(AJ9:AK9)-AVERAGE(AF9:AI9)) -> 5.9716892 | AM9: =AL9-$AJ$36 -> 0.57814773 | AN9: =2^-AM9 -> 0.66982321
B10: C1 3d | C10: 13 | D10: 23.345695 | E10: 22.64711 | F10: 22.738323 | G10: 21.647028 | I10: 27.195425 | J10: =(AVERAGE(H10:I10)-AVERAGE(D10:G10)) -> 4.6008859 | K10: =J10-$J$54 -> 0.41766135 | L10: =2^-K10 -> 0.7486372 | P10: C1 3d | Q10: 13 | R10: 23.345695 | S10: 22.64711 | T10: 22.738323 | U10: 21.647028 | V10: 19.567888 | W10: 19.636452 | X10: =(AVERAGE(V10:W10)-AVERAGE(R10:U10)) -> -2.9923692 | Y10: =X10-$X$54 -> -0.8287665 | Z10: =2^-Y10 -> 1.7761661 | AD10: C1 3d | AE10: 13 | AF10: 23.345695 | AG10: 22.64711 | AH10: 22.738323 | AI10: 21.647028 | AJ10: 29.119991 | AK10: 26.842112 | AL10: =(AVERAGE(AJ10:AK10)-AVERAGE(AF10:AI10)) -> 5.3865123 | AM10: =AL10-$AJ$37 -> 0.12929122 | AN10: =2^-AM10 -> 0.91428052
B11: C2 3d | C11: 14 | D11: 22.612711 | E11: 22.57996 | F11: 21.063808 | G11: 19.416796 | H11: 25.147491 | I11: 26.293026 | J11: =(AVERAGE(H11:I11)-AVERAGE(D11:G11)) -> 4.30194 | K11: =J11-$J$54 -> 0.11871545 | L11: =2^-K11 -> 0.92100734 | P11: C2 3d | Q11: 14 | R11: 22.612711 | S11: 22.57996 | T11: 21.063808 | U11: 19.416796 | V11: 19.332747 | W11: 19.651995 | X11: =(AVERAGE(V11:W11)-AVERAGE(R11:U11)) -> -1.9259481 | Y11: =X11-$X$54 -> 0.23765453 | Z11: =2^-Y11 -> 0.84812303 | AD11: C2 3d | AE11: 14 | AF11: 22.612711 | AG11: 22.57996 | AH11: 21.063808 | AI11: 19.416796 | AJ11: 27.531897 | AK11: 25.885597 | AL11: =(AVERAGE(AJ11:AK11)-AVERAGE(AF11:AI11)) -> 5.2904282 | AM11: =AL11-$AJ$37 -> 0.033207099 | AN11: =2^-AM11 -> 0.97724547
B12: C3 3d | C12: 15 | D12: 22.042751 | E12: 22.206158 | F12: 20.22966 | G12: 20.15831 | H12: 24.454449 | I12: 25.157686 | J12: =(AVERAGE(H12:I12)-AVERAGE(D12:G12)) -> 3.6468477 | K12: =J12-$J$54 -> -0.53637679 | L12: =2^-K12 -> 1.4503256 | P12: C3 3d | Q12: 15 | R12: 22.042751 | S12: 22.206158 | T12: 20.22966 | U12: 20.15831 | V12: 19.744747 | W12: 19.428711 | X12: =(AVERAGE(V12:W12)-AVERAGE(R12:U12)) -> -1.5724907 | Y12: =X12-$X$54 -> 0.59111198 | Z12: =2^-Y12 -> 0.66383105 | AD12: C3 3d | AE12: 15 | AF12: 22.042751 | AG12: 22.206158 | AH12: 20.22966 | AI12: 20.15831 | AJ12: 26.582962 | AK12: 25.924923 | AL12: =(AVERAGE(AJ12:AK12)-AVERAGE(AF12:AI12)) -> 5.0947227 | AM12: =AL12-$AJ$37 -> -0.16249832 | AN12: =2^-AM12 -> 1.1192236
B13: Bm 1 3d | C13: 16 | D13: 21.012499 | E13: 21.45314 | F13: 18.852619 | G13: 18.145897 | H13: 25.562408 | I13: 25.229315 | J13: =(AVERAGE(H13:I13)-AVERAGE(D13:G13)) -> 5.5298228 | K13: =J13-$J$54 -> 1.3465983 | L13: =2^-K13 -> 0.39321812 | P13: Bm 1 3d | Q13: 16 | R13: 21.012499 | S13: 21.45314 | T13: 18.852619 | U13: 18.145897 | V13: 18.730783 | W13: 18.329363 | X13: =(AVERAGE(V13:W13)-AVERAGE(R13:U13)) -> -1.3359656 | Y13: =X13-$X$54 -> 0.82763704 | Z13: =2^-Y13 -> 0.56345135 | AD13: Bm 1 3d | AE13: 16 | AF13: 21.012499 | AG13: 21.45314 | AH13: 18.852619 | AI13: 18.145897 | AJ13: 25.170755 | AK13: 24.975912 | AL13: =(AVERAGE(AJ13:AK13)-AVERAGE(AF13:AI13)) -> 5.2072949 | AM13: =AL13-$AJ$37 -> -0.049926122 | AN13: =2^-AM13 -> 1.0352119
B14: Bm2 3d | C14: 17 | D14: 22.834578 | E14: 22.680689 | F14: 21.780043 | G14: 20.533335 | H14: 29.693943 | I14: 27.915049 | J14: =(AVERAGE(H14:I14)-AVERAGE(D14:G14)) -> 6.8473349 | K14: =J14-$J$54 -> 2.6641103 | L14: =2^-K14 -> 0.15776944 | P14: Bm2 3d | Q14: 17 | R14: 22.834578 | S14: 22.680689 | T14: 21.780043 | U14: 20.533335 | V14: 21.182232 | W14: 20.912151 | X14: =(AVERAGE(V14:W14)-AVERAGE(R14:U14)) -> -0.90996933 | Y14: =X14-$X$54 -> 1.2536333 | Z14: =2^-Y14 -> 0.41939067 | AD14: Bm2 3d | AE14: 17 | AF14: 22.834578 | AG14: 22.680689 | AH14: 21.780043 | AI14: 20.533335 | AJ14: 27.996984 | AK14: 28.276325 | AL14: =(AVERAGE(AJ14:AK14)-AVERAGE(AF14:AI14)) -> 6.1794939 | AM14: =AL14-$AJ$37 -> 0.92227284 | AN14: =2^-AM14 -> 0.52767706
B15: Bm 3 3d | C15: 18 | D15: 23.832172 | E15: 23.386063 | F15: 22.37434 | G15: 21.154541 | H15: 27.96884 | I15: 28.660032 | J15: =(AVERAGE(H15:I15)-AVERAGE(D15:G15)) -> 5.6276569 | K15: =J15-$J$54 -> 1.4444324 | L15: =2^-K15 -> 0.36743669 | P15: Bm 3 3d | Q15: 18 | R15: 23.832172 | S15: 23.386063 | T15: 22.37434 | U15: 21.154541 | V15: 20.808403 | W15: 21.487812 | X15: =(AVERAGE(V15:W15)-AVERAGE(R15:U15)) -> -1.5386715 | Y15: =X15-$X$54 -> 0.62493118 | Z15: =2^-Y15 -> 0.64845071 | AD15: Bm 3 3d | AE15: 18 | AF15: 23.832172 | AG15: 23.386063 | AH15: 22.37434 | AI15: 21.154541 | AJ15: 29.282314 | AK15: 27.616253 | AL15: =(AVERAGE(AJ15:AK15)-AVERAGE(AF15:AI15)) -> 5.7625046 | AM15: =AL15-$AJ$37 -> 0.50528351 | AN15: =2^-AM15 -> 0.70452191
B16: C1 4d | C16: 19 | D16: 23.75663 | E16: 23.712858 | F16: 17.980774 | G16: 17.505638 | H16: 27.745232 | I16: 26.26825 | J16: =(AVERAGE(H16:I16)-AVERAGE(D16:G16)) -> 6.2677655 | K16: =J16-$J$55 -> 0.63404036 | L16: =2^-K16 -> 0.64436929 | P16: C1 4d | Q16: 19 | R16: 23.75663 | S16: 23.712858 | T16: 17.980774 | U16: 17.505638 | V16: 21.42804 | W16: 20.940527 | X16: =(AVERAGE(V16:W16)-AVERAGE(R16:U16)) -> 0.44530821 | Y16: =X16-$X$55 -> 0.23977296 | Z16: =2^-Y16 -> 0.84687858 | AD16: C1 5d | AE16: 25 | AF16: 22.130222 | AG16: 21.650995 | AH16: 21.003397 | AI16: 20.653542 | AJ16: 26.526417 | AK16: 26.960852 | AL16: =(AVERAGE(AJ16:AK16)-AVERAGE(AF16:AI16)) -> 5.3840952 | AM16: =AL16-$AJ$38 -> -0.2219739 | AN16: =2^-AM16 -> 1.1663283
B17: C2 4d | C17: 20 | D17: 23.130978 | E17: 23.688139 | F17: 19.6371 | G17: 17.468639 | H17: 26.41782 | I17: 26.168133 | J17: =(AVERAGE(H17:I17)-AVERAGE(D17:G17)) -> 5.3117623 | K17: =J17-$J$55 -> -0.32196283 | L17: =2^-K17 -> 1.2500301 | P17: C2 4d | Q17: 20 | R17: 23.130978 | S17: 23.688139 | T17: 19.6371 | U17: 17.468639 | V17: 21.311577 | W17: 20.704929 | X17: =(AVERAGE(V17:W17)-AVERAGE(R17:U17)) -> 0.027039051 | Y17: =X17-$X$55 -> -0.1784962 | Z17: =2^-Y17 -> 1.1317036 | AD17: C2 5d | AE17: 26 | AF17: 21.242998 | AG17: 21.288979 | AH17: 19.556295 | AI17: 20.136721 | AJ17: 26.34037 | AK17: 26.882698 | AL17: =(AVERAGE(AJ17:AK17)-AVERAGE(AF17:AI17)) -> 6.0552859 | AM17: =AL17-$AJ$38 -> 0.44921684 | AN17: =2^-AM17 -> 0.73244034
B18: C3 4d | C18: 21 | D18: 23.851402 | E18: 23.511002 | F18: 19.177872 | G18: 19.09478 | H18: 26.379051 | I18: 27.081772 | J18: =(AVERAGE(H18:I18)-AVERAGE(D18:G18)) -> 5.3216476 | K18: =J18-$J$55 -> -0.31207752 | L18: =2^-K18 -> 1.2414942 | P18: C3 4d | Q18: 21 | R18: 23.851402 | S18: 23.511002 | T18: 19.177872 | U18: 19.09478 | V18: 21.31085 | W18: 21.795195 | X18: =(AVERAGE(V18:W18)-AVERAGE(R18:U18)) -> 0.1442585 | Y18: =X18-$X$55 -> -0.061276754 | Z18: =2^-Y18 -> 1.0433887 | AD18: C3 5d | AE18: 27 | AF18: 20.672461 | AG18: 21.473396 | AH18: 20.998573 | AI18: 20.286203 | AJ18: 26.332502 | AK18: 26.140467 | AL18: =(AVERAGE(AJ18:AK18)-AVERAGE(AF18:AI18)) -> 5.3788261 | AM18: =AL18-$AJ$38 -> -0.22724295 | AN18: =2^-AM18 -> 1.1705958
B19: Bm 1 4d | C19: 22 | D19: 22.788944 | E19: 23.788052 | F19: 16.797829 | G19: 16.11553 | H19: 26.722025 | J19: =(AVERAGE(H19:I19)-AVERAGE(D19:G19)) -> 6.8494363 | K19: =J19-$J$55 -> 1.2157111 | L19: =2^-K19 -> 0.4305608 | P19: Bm 1 4d | Q19: 22 | R19: 22.788944 | S19: 23.788052 | T19: 16.797829 | U19: 16.11553 | V19: 20.856464 | W19: 21.362583 | X19: =(AVERAGE(V19:W19)-AVERAGE(R19:U19)) -> 1.2369351 | Y19: =X19-$X$55 -> 1.0313999 | Z19: =2^-Y19 -> 0.4892352 | AD19: Bm 1 5d | AE19: 28 | AF19: 25.482094 | AG19: 25.213163 | AI19: 22.591633 | AJ19: 28.518456 | AK19: 28.63541 | AL19: =(AVERAGE(AJ19:AK19)-AVERAGE(AF19:AI19)) -> 4.1479696 | AM19: =AL19-$AJ$38 -> -1.4580995 | AN19: =2^-AM19 -> 2.747462
B20: Bm2 4d | C20: 23 | D20: 22.090874 | E20: 22.186308 | F20: 17.172258 | G20: 16.408842 | H20: 22.914772 | I20: 25.467049 | J20: =(AVERAGE(H20:I20)-AVERAGE(D20:G20)) -> 4.7263398 | K20: =J20-$J$55 -> -0.90738535 | L20: =2^-K20 -> 1.8756431 | P20: Bm2 4d | Q20: 23 | R20: 22.090874 | S20: 22.186308 | T20: 17.172258 | U20: 16.408842 | V20: 17.852877 | W20: 18.348011 | X20: =(AVERAGE(V20:W20)-AVERAGE(R20:U20)) -> -1.3641267 | Y20: =X20-$X$55 -> -1.5696619 | Z20: =2^-Y20 -> 2.9683515 | AD20: Bm2 5d | AE20: 29 | AF20: 21.397427 | AG20: 22.360268 | AH20: 19.469219 | AI20: 19.481897 | AJ20: 27.76157 | AK20: 27.959574 | AL20: =(AVERAGE(AJ20:AK20)-AVERAGE(AF20:AI20)) -> 7.1833692 | AM20: =AL20-$AJ$38 -> 1.5773001 | AN20: =2^-AM20 -> 0.33510844
B21: Bm 3 4d | C21: 24 | D21: 22.689152 | E21: 22.64785 | F21: 18.612457 | G21: 18.1621 | H21: 24.519018 | I21: 27.597687 | J21: =(AVERAGE(H21:I21)-AVERAGE(D21:G21)) -> 5.5304627 | K21: =J21-$J$55 -> -0.10326242 | L21: =2^-K21 -> 1.0741998 | P21: Bm 3 4d | Q21: 24 | R21: 22.689152 | S21: 22.64785 | T21: 18.612457 | U21: 18.1621 | V21: 20.812447 | W21: 20.232615 | X21: =(AVERAGE(V21:W21)-AVERAGE(R21:U21)) -> -0.0053591728 | Y21: =X21-$X$55 -> -0.21089443 | Z21: =2^-Y21 -> 1.1574055 | AD21: Bm 3 5d | AE21: 30 | AF21: 23.315302 | AG21: 23.295767 | AH21: 22.262863 | AI21: 21.694347 | AJ21: 28.474548 | AK21: 27.829439 | AL21: =(AVERAGE(AJ21:AK21)-AVERAGE(AF21:AI21)) -> 5.5099239 | AM21: =AL21-$AJ$38 -> -0.096145153 | AN21: =2^-AM21 -> 1.0689135
B22: C1 5d | C22: 25 | D22: 22.130222 | E22: 21.650995 | F22: 21.003397 | G22: 20.653542 | H22: 28.430086 | I22: 28.078693 | J22: =(AVERAGE(H22:I22)-AVERAGE(D22:G22)) -> 6.8948507 | K22: =J22-$J$56 -> -0.21629413 | L22: =2^-K22 -> 1.1617456 | P22: C1 5d | Q22: 25 | R22: 22.130222 | S22: 21.650995 | T22: 21.003397 | U22: 20.653542 | V22: 25.872694 | W22: 25.804256 | X22: =(AVERAGE(V22:W22)-AVERAGE(R22:U22)) -> 4.4789362 | Y22: =X22-$X$56 -> -0.35503626 | Z22: =2^-Y22 -> 1.2790177 | AD22: C1 7d | AE22: 37 | AF22: 23.398689 | AG22: 23.143154 | AI22: 22.087042 | AJ22: 28.712782 | AK22: 28.749775 | AL22: =(AVERAGE(AJ22:AK22)-AVERAGE(AF22:AI22)) -> 5.8549833 | AM22: =AL22-$AJ$39 -> 0.07885562 | AN22: =2^-AM22 -> 0.94680838
B23: C2 5d | C23: 26 | D23: 21.242998 | E23: 21.288979 | F23: 19.556295 | G23: 20.136721 | H23: 28.015543 | I23: 27.906311 | J23: =(AVERAGE(H23:I23)-AVERAGE(D23:G23)) -> 7.4046788 | K23: =J23-$J$56 -> 0.29353396 | L23: =2^-K23 -> 0.81590101 | P23: C2 5d | Q23: 26 | R23: 21.242998 | S23: 21.288979 | T23: 19.556295 | U23: 20.136721 | V23: 24.922926 | W23: 25.479542 | X23: =(AVERAGE(V23:W23)-AVERAGE(R23:U23)) -> 4.6449857 | Y23: =X23-$X$56 -> -0.18898678 | Z23: =2^-Y23 -> 1.1399628 | AD23: C2 7d | AE23: 38 | AF23: 23.209871 | AG23: 23.394863 | AH23: 21.836922 | AJ23: 27.684017 | AK23: 28.156311 | AL23: =(AVERAGE(AJ23:AK23)-AVERAGE(AF23:AI23)) -> 5.1062787 | AM23: =AL23-$AJ$39 -> -0.66984897 | AN23: =2^-AM23 -> 1.5909064
B24: C3 5d | C24: 27 | D24: 20.672461 | E24: 21.473396 | F24: 20.998573 | G24: 20.286203 | H24: 27.990288 | I24: 27.792839 | J24: =(AVERAGE(H24:I24)-AVERAGE(D24:G24)) -> 7.033905 | K24: =J24-$J$56 -> -0.077239831 | L24: =2^-K24 -> 1.0549977 | P24: C3 5d | Q24: 27 | R24: 20.672461 | S24: 21.473396 | T24: 20.998573 | U24: 20.286203 | V24: 26.363192 | W24: 26.108116 | X24: =(AVERAGE(V24:W24)-AVERAGE(R24:U24)) -> 5.3779955 | Y24: =X24-$X$56 -> 0.54402304 | Z24: =2^-Y24 -> 0.68585569 | AD24: C3 7d | AE24: 39 | AF24: =AVERAGE(AF22:AF23) -> 23.30428 | AH24: 31.127039 | AI24: 30.850796 | AJ24: 33.640972 | AK24: 35.948013 | AL24: =(AVERAGE(AJ24:AK24)-AVERAGE(AF24:AI24)) -> 6.3671211 | AM24: =AL24-$AJ$39 -> 0.59099335 | AN24: =AVERAGE(AN22:AN23) -> 1.2688574
B25: Bm 1 5d | C25: 28 | D25: 25.482094 | E25: 25.213163 | G25: 22.591633 | H25: 30.052397 | I25: 29.633871 | J25: =(AVERAGE(H25:I25)-AVERAGE(D25:G25)) -> 5.4141706 | K25: =J25-$J$56 -> -1.6969743 | L25: =2^-K25 -> 3.2422027 | P25: Bm 1 5d | Q25: 28 | R25: 25.482094 | S25: 25.213163 | T25: 24.936951 | U25: 22.591633 | V25: 28.3402 | W25: 29.149803 | X25: =(AVERAGE(V25:W25)-AVERAGE(R25:U25)) -> 4.1890416 | Y25: =X25-$X$56 -> -0.64493084 | Z25: =2^-Y25 -> 1.5636643 | AD25: Bm 1 7d | AE25: 40 | AF25: 24.254467 | AG25: 24.512037 | AH25: 22.484402 | AI25: 22.659548 | AJ25: 29.828554 | AK25: 27.761818 | AL25: =(AVERAGE(AJ25:AK25)-AVERAGE(AF25:AI25)) -> 5.3175726 | AM25: =AL25-$AJ$39 -> -0.45855512 | AN25: =2^-AM25 -> 1.3741649
B26: Bm2 5d | C26: 29 | D26: 21.397427 | E26: 22.360268 | F26: 19.469219 | G26: 19.481897 | H26: 27.80266 | I26: 27.112232 | J26: =(AVERAGE(H26:I26)-AVERAGE(D26:G26)) -> 6.7802434 | K26: =J26-$J$56 -> -0.33090146 | L26: =2^-K26 -> 1.2577991 | P26: Bm2 5d | Q26: 29 | R26: 21.397427 | S26: 22.360268 | T26: 19.469219 | U26: 19.481897 | V26: 25.755611 | W26: 27.77602 | X26: =(AVERAGE(V26:W26)-AVERAGE(R26:U26)) -> 6.088613 | Y26: =X26-$X$56 -> 1.2546406 | Z26: =2^-Y26 -> 0.41909796 | AD26: Bm2 7d | AE26: 41 | AF26: 24.466396 | AG26: 24.136328 | AH26: 22.053213 | AI26: 22.400589 | AJ26: 28.315805 | AK26: 27.887474 | AL26: =(AVERAGE(AJ26:AK26)-AVERAGE(AF26:AI26)) -> 4.8375082 | AM26: =AL26-$AJ$39 -> -0.93861951 | AN26: =2^-AM26 -> 1.9166933
B27: Bm 3 5d | C27: 30 | D27: 23.315302 | E27: 23.295767 | F27: 22.262863 | G27: 21.694347 | H27: =AVERAGE(H25:H26) -> 28.927528 | J27: =(AVERAGE(H27:I27)-AVERAGE(D27:G27)) -> 6.2854586 | K27: =J27-$J$56 -> -0.8256863 | L27: =2^-K27 -> 1.772378 | P27: Bm 3 5d | Q27: 30 | R27: 23.315302 | S27: 23.295767 | T27: 22.262863 | U27: 21.694347 | V27: 28.626881 | W27: 28.719343 | X27: =(AVERAGE(V27:W27)-AVERAGE(R27:U27)) -> 6.0310421 | Y27: =X27-$X$56 -> 1.1970696 | Z27: =2^-Y27 -> 0.4361603 | AD27: Bm 3 7d | AE27: 42 | AF27: 24.173578 | AG27: 24.229919 | AH27: 22.666315 | AI27: 21.813253 | AJ27: 27.418608 | AK27: =AVERAGE(AJ26:AK26) -> 28.10164 | AL27: =(AVERAGE(AJ27:AK27)-AVERAGE(AF27:AI27)) -> 4.5393572 | AM27: =AL27-$AJ$39 -> -1.2367705 | AN27: =2^-AM27 -> 2.3567039
B28: C1 6d | C28: 31 | D28: 23.186012 | E28: 23.137756 | F28: 17.807966 | G28: 17.894079 | H28: 29.313189 | I28: 28.990728 | J28: =(AVERAGE(H28:I28)-AVERAGE(D28:G28)) -> 8.645505 | K28: =J28-$J$57 -> 0.59219265 | L28: =2^-K28 -> 0.66333399 | P28: C1 6d | Q28: 31 | R28: 23.186012 | S28: 23.137756 | T28: 17.807966 | U28: 17.894079 | V28: 20.822639 | W28: 20.710474 | X28: =(AVERAGE(V28:W28)-AVERAGE(R28:U28)) -> 0.26010323 | Y28: =X28-$X$57 -> 0.37124316 | Z28: =2^-Y28 -> 0.77311602 | AD28: C1 9d | AE28: 49 | AF28: 25.075951 | AG28: 25.552391 | AH28: 22.816856 | AI28: 22.344206 | AJ28: 27.895035 | AK28: 27.141615 | AL28: =(AVERAGE(AJ28:AK28)-AVERAGE(AF28:AI28)) -> 3.5709739 | AM28: =AL28-$AJ$40 -> -0.43002653 | AN28: =2^-AM28 -> 1.3472584
B29: C2 6d | C29: 32 | D29: 22.721123 | E29: 22.645586 | F29: 18.269285 | G29: 16.487997 | I29: 27.835989 | J29: =(AVERAGE(H29:I29)-AVERAGE(D29:G29)) -> 7.8049912 | K29: =J29-$J$57 -> -0.24832106 | L29: =2^-K29 -> 1.187824 | P29: C2 6d | Q29: 32 | R29: 22.721123 | S29: 22.645586 | T29: 18.269285 | U29: 16.487997 | V29: 19.944881 | W29: 19.756725 | X29: =(AVERAGE(V29:W29)-AVERAGE(R29:U29)) -> -0.18019438 | Y29: =X29-$X$57 -> -0.069054445 | Z29: =2^-Y29 -> 1.0490289 | AD29: C2 9d | AE29: 50 | AF29: 24.32523 | AG29: 24.426992 | AH29: 20.805058 | AI29: 21.153971 | AJ29: 27.482225 | AK29: 27.300201 | AL29: =(AVERAGE(AJ29:AK29)-AVERAGE(AF29:AI29)) -> 4.7134008 | AM29: =AL29-$AJ$40 -> 0.71240044 | AN29: =2^-AM29 -> 0.61030384
B30: C3 6d | C30: 33 | D30: 23.384022 | E30: 23.311583 | F30: 19.378029 | G30: 18.377132 | H30: 28.126972 | I30: 29.517292 | J30: =(AVERAGE(H30:I30)-AVERAGE(D30:G30)) -> 7.7094407 | K30: =J30-$J$57 -> -0.34387159 | L30: =2^-K30 -> 1.2691579 | P30: C3 6d | Q30: 33 | R30: 23.384022 | S30: 23.311583 | T30: 19.378029 | U30: 18.377132 | V30: 21.453163 | W30: 19.945562 | X30: =(AVERAGE(V30:W30)-AVERAGE(R30:U30)) -> -0.41332865 | Y30: =X30-$X$57 -> -0.30218871 | Z30: =2^-Y30 -> 1.2330136 | AD30: C3 9d | AE30: 51 | AF30: 24.589403 | AG30: 24.405466 | AH30: 21.749001 | AI30: 21.121328 | AJ30: 26.816687 | AK30: 26.553165 | AL30: =(AVERAGE(AJ30:AK30)-AVERAGE(AF30:AI30)) -> 3.7186265 | AM30: =AL30-$AJ$40 -> -0.28237391 | AN30: =2^-AM30 -> 1.2161944
B31: Bm 1 6d | C31: 34 | D31: 19.92444 | E31: 20.117538 | F31: 16.629742 | G31: 14.34235 | H31: 26.632624 | J31: =(AVERAGE(H31:I31)-AVERAGE(D31:G31)) -> 8.879106 | K31: =J31-$J$57 -> 0.82579374 | L31: =2^-K31 -> 0.56417172 | P31: Bm 1 6d | Q31: 34 | R31: 19.92444 | S31: 20.117538 | T31: 16.629742 | U31: 14.34235 | V31: 19.2244 | W31: 19.603775 | X31: =(AVERAGE(V31:W31)-AVERAGE(R31:U31)) -> 1.6605697 | Y31: =X31-$X$57 -> 1.7717096 | Z31: =2^-Y31 -> 0.29286149 | AD31: Bm 1 9d | AE31: 52 | AF31: 25.208462 | AG31: 25.326752 | AH31: 21.73633 | AI31: 21.520866 | AJ31: 27.075428 | AK31: 27.21867 | AL31: =(AVERAGE(AJ31:AK31)-AVERAGE(AF31:AI31)) -> 3.6989465 | AM31: =AL31-$AJ$40 -> -0.30205393 | AN31: =2^-AM31 -> 1.2328984
B32: Bm2 6d | C32: 35 | D32: 22.764437 | E32: 22.895998 | F32: 19.288746 | G32: 18.920383 | H32: 28.197559 | I32: 28.608381 | J32: =(AVERAGE(H32:I32)-AVERAGE(D32:G32)) -> 7.4355793 | K32: =J32-$J$57 -> -0.617733 | L32: =2^-K32 -> 1.5344621 | P32: Bm2 6d | Q32: 35 | R32: 22.764437 | S32: 22.895998 | T32: 19.288746 | U32: 18.920383 | V32: 20.783791 | W32: 20.59255 | X32: =(AVERAGE(V32:W32)-AVERAGE(R32:U32)) -> -0.27922058 | Y32: =X32-$X$57 -> -0.16808065 | Z32: =2^-Y32 -> 1.1235627 | AD32: Bm2 9d | AE32: 53 | AF32: 24.768927 | AG32: 25.014923 | AH32: 21.967373 | AI32: 21.547497 | AJ32: 26.602541 | AK32: 26.820648 | AL32: =(AVERAGE(AJ32:AK32)-AVERAGE(AF32:AI32)) -> 3.3869147 | AM32: =AL32-$AJ$40 -> -0.61408567 | AN32: =2^-AM32 -> 1.5305877
B33: Bm 3 6d | C33: 36 | D33: 22.755032 | E33: 22.501596 | F33: 17.951269 | G33: 15.451588 | H33: 26.734798 | I33: 27.995167 | J33: =(AVERAGE(H33:I33)-AVERAGE(D33:G33)) -> 7.7001114 | K33: =J33-$J$57 -> -0.35320091 | L33: =2^-K33 -> 1.2773916 | P33: Bm 3 6d | Q33: 36 | R33: 22.755032 | S33: 22.501596 | T33: 17.951269 | U33: 15.451588 | V33: 20.501608 | W33: 20.836742 | X33: =(AVERAGE(V33:W33)-AVERAGE(R33:U33)) -> 1.0043039 | Y33: =X33-$X$57 -> 1.1154439 | Z33: =2^-Y33 -> 0.46154913 | AD33: Bm 3 9d | AE33: 54 | AG33: 24.466694 | AH33: 21.499489 | AI33: 22.336283 | AJ33: 26.54211 | AK33: 26.607286 | AL33: =(AVERAGE(AJ33:AK33)-AVERAGE(AF33:AI33)) -> 3.80721 | AM33: =AL33-$AJ$40 -> -0.19379044 | AN33: =2^-AM33 -> 1.1437648
B34: C1 7d | C34: 37 | D34: 23.398689 | E34: 23.143154 | F34: 20.929424 | G34: 22.087042 | H34: 30.311625 | I34: 30.221291 | J34: =(AVERAGE(H34:I34)-AVERAGE(D34:G34)) -> 7.8768802 | K34: =J34-$J$58 -> 0.67040316 | L34: =2^-K34 -> 0.62833107 | P34: C1 7d | Q34: 37 | R34: 23.398689 | S34: 23.143154 | T34: 20.929424 | U34: 22.087042 | V34: 27.530617 | W34: 26.812742 | X34: =(AVERAGE(V34:W34)-AVERAGE(R34:U34)) -> 4.7821021 | Y34: =X34-$X$58 -> 0.6252576 | Z34: =2^-Y34 -> 0.64830401
B35: C2 7d | C35: 38 | D35: 23.209871 | E35: 23.394863 | F35: 21.836922 | G35: =AVERAGE(F34:F35) -> 21.383173 | H35: 28.986437 | I35: 28.925531 | J35: =(AVERAGE(H35:I35)-AVERAGE(D35:G35)) -> 6.4997768 | K35: =J35-$J$58 -> -0.70670017 | L35: =2^-K35 -> 1.6320669 | P35: C2 7d | Q35: 38 | R35: 23.209871 | S35: 23.394863 | T35: 21.836922 | V35: 26.44907 | W35: 25.900293 | X35: =(AVERAGE(V35:W35)-AVERAGE(R35:U35)) -> 3.3607963 | Y35: =X35-$X$58 -> -0.79604822 | Z35: =2^-Y35 -> 1.7363385
B36: C3 7d | C36: 39 | D36: =AVERAGE(D34:D35) -> 23.30428 | F36: =AVERAGE(F34:G34) -> 21.508233 | H36: =AVERAGE(H34:H35) -> 29.649031 | J36: =(AVERAGE(H36:I36)-AVERAGE(D36:G36)) -> 7.242774 | K36: =J36-$J$58 -> 0.036297003 | L36: =2^-K36 -> 0.97515469 | P36: C3 7d | Q36: 39 | R36: =AVERAGE(R34:R35) -> 23.30428 | T36: 31.127039 | U36: 30.850796 | V36: 32.638004 | W36: 32.872009 | X36: =(AVERAGE(V36:W36)-AVERAGE(R36:U36)) -> 4.3276351 | Y36: =X36-$X$58 -> 0.17079062 | Z36: =AVERAGE(Z34:Z35) -> 1.1923212 | AI36: 1d | AJ36: =AVERAGE(AL4:AL6) -> 5.3935415
B37: Bm 1 7d | C37: 40 | D37: 24.254467 | E37: 24.512037 | F37: 22.484402 | G37: 22.659548 | H37: 30.039825 | I37: 30.180965 | J37: =(AVERAGE(H37:I37)-AVERAGE(D37:G37)) -> 6.632782 | K37: =J37-$J$58 -> -0.57369502 | L37: =2^-K37 -> 1.4883306 | P37: Bm 1 7d | Q37: 40 | R37: 24.254467 | S37: 24.512037 | T37: 22.484402 | U37: 22.659548 | V37: 26.208107 | W37: 26.198566 | X37: =(AVERAGE(V37:W37)-AVERAGE(R37:U37)) -> 2.7257233 | Y37: =X37-$X$58 -> -1.4311212 | Z37: =2^-Y37 -> 2.6965621 | AI37: 3d | AJ37: =AVERAGE(AL10:AL12) -> 5.2572211
B38: Bm2 7d | C38: 41 | D38: 24.466396 | E38: 24.136328 | F38: 22.053213 | G38: 22.400589 | H38: 29.964874 | I38: 28.933453 | J38: =(AVERAGE(H38:I38)-AVERAGE(D38:G38)) -> 6.1850319 | K38: =J38-$J$58 -> -1.0214451 | L38: =2^-K38 -> 2.0299513 | P38: Bm2 7d | Q38: 41 | R38: 24.466396 | S38: 24.136328 | T38: 22.053213 | U38: 22.400589 | V38: 28.036987 | W38: 27.172014 | X38: =(AVERAGE(V38:W38)-AVERAGE(R38:U38)) -> 4.3403692 | Y38: =X38-$X$58 -> 0.18352471 | Z38: =2^-Y38 -> 0.88054906 | AI38: 5d | AJ38: =AVERAGE(AL16:AL18) -> 5.6060691
B39: Bm 3 7d | C39: 42 | D39: 24.173578 | E39: 24.229919 | F39: 22.666315 | G39: 21.813253 | H39: =AVERAGE(I37:I38) -> 29.557209 | J39: =(AVERAGE(H39:I39)-AVERAGE(D39:G39)) -> 6.3364425 | K39: =J39-$J$58 -> -0.87003454 | L39: =2^-K39 -> 1.8277067 | P39: Bm 3 7d | Q39: 42 | R39: 24.173578 | S39: 24.229919 | T39: 22.666315 | U39: 21.813253 | V39: 24.569788 | W39: 24.791063 | X39: =(AVERAGE(V39:W39)-AVERAGE(R39:U39)) -> 1.4596591 | Y39: =X39-$X$58 -> -2.6971854 | Z39: =2^-Y39 -> 6.4853544 | AI39: 7d | AJ39: =AVERAGE(AL22:AL24) -> 5.7761277
B40: C1 8d | C40: 43 | D40: 24.43059 | E40: 24.573454 | F40: 21.28845 | G40: 21.822668 | H40: 22.864216 | I40: 22.431517 | J40: =(AVERAGE(H40:I40)-AVERAGE(D40:G40)) -> -0.38092422 | K40: =J40-$J$59 -> -0.41922537 | L40: =2^-K40 -> 1.3372094 | P40: C1 8d | Q40: 43 | R40: 24.43059 | S40: 24.573454 | T40: 21.28845 | U40: 21.822668 | V40: 26.138163 | W40: 25.741388 | X40: =(AVERAGE(V40:W40)-AVERAGE(R40:U40)) -> 2.910985 | Y40: =X40-$X$59 -> -0.57779344 | Z40: =2^-Y40 -> 1.4925647 | AI40: 9d | AJ40: =AVERAGE(AL28:AL30) -> 4.0010004
B41: C2 8d | C41: 44 | D41: 23.017653 | E41: 23.041599 | F41: 20.931124 | G41: 20.001276 | H41: 21.227573 | I41: 21.417307 | J41: =(AVERAGE(H41:I41)-AVERAGE(D41:G41)) -> -0.42547274 | K41: =J41-$J$59 -> -0.46377389 | L41: =2^-K41 -> 1.3791448 | P41: C2 8d | Q41: 44 | R41: 23.017653 | S41: 23.041599 | T41: 20.931124 | U41: 20.001276 | V41: 26.622063 | W41: 24.979567 | X41: =(AVERAGE(V41:W41)-AVERAGE(R41:U41)) -> 4.0529017 | Y41: =X41-$X$59 -> 0.56412331 | Z41: =2^-Y41 -> 0.6763663 | AE41: C | AF41: Error | AG41: Bm | AH41: Error
...

Sheet Genes RAIZ
E1: EF | G1: LOXD | Q1: EF | S1: OPR3 | AF1: EF | AG1: ICS | AS1: EF | AU1: MYC2
C2: Sample | E2: Housekeeping gene | F2: Gene of interest | G2: Gene of interest | H2: ΔCt(Ct gene interest - Ct housekeeping gene) | I2: ΔΔCt(ΔCt muestra - ΔCt control average) | J2: 2^-(ΔΔCt) | K2: log | O2: Sample | Q2: Housekeeping gene | S2: Gene of interest | T2: ΔCt(Ct gene interest - Ct housekeeping gene) | U2: ΔΔCt(ΔCt muestra - ΔCt control average) | V2: 2^-(ΔΔCt) | W2: log | AD2: Sample | AE2: Housekeeping gene | AF2: Housekeeping gene | AG2: Gene of interest | AH2: Gene of interest | AI2: ΔCt(Ct gene interest - Ct housekeeping gene) | AJ2: ΔΔCt(ΔCt muestra - ΔCt control average) | AK2: 2^-(ΔΔCt) | AL2: log | AQ2: Sample | AR2: Housekeeping gene | AS2: Housekeeping gene | AT2: Gene of interest | AU2: Gene of interest | AV2: ΔCt(Ct gene interest - Ct housekeeping gene) | AW2: ΔΔCt(ΔCt muestra - ΔCt control average) | AX2: 2^-(ΔΔCt) | AY2: log
B3: C1 3d | C3: 13 | D3: 23.071939 | E3: 22.264887 | F3: 23.373026 | G3: 23.521111 | H3: =(AVERAGE(F3:G3)-AVERAGE(D3:E3)) -> 0.77865505 | I3: =H3-$H$41 -> -0.62745794 | J3: =2^-I3 -> 1.5448405 | N3: C1 3d | O3: 13 | P3: 23.071939 | Q3: 22.264887 | R3: 19.613838 | S3: 19.181236 | T3: =(AVERAGE(R3:S3)-AVERAGE(P3:Q3)) -> -3.2708759 | U3: =T3-$T$47 -> -0.74968688 | V3: =2^-U3 -> 1.6814279 | AC3: C1 1d | AD3: 1 | AE3: =AVERAGE(AE4:AE5) -> 24.916069 | AF3: =AVERAGE(AF4:AF5) -> 24.364873 | AG3: 29.597382 | AH3: 28.577679 | AI3: =(AVERAGE(AG3:AH3)-AVERAGE(AE3:AF3)) -> 4.4470592 | AJ3: =AI3-$AG$35 -> 0.86470668 | AK3: =2^-AJ3 -> 0.54915805 | AL3: =LOG(AK3,2) -> -0.86470668 | AP3: C1 7d | AQ3: 37 | AR3: =AVERAGE(AS3:AS4) -> 22.803472 | AS3: 23.64431 | AT3: 26.918276 | AU3: 26.943851 | AV3: =(AVERAGE(AT3:AU3)-AVERAGE(AR3:AS3)) -> 3.7071729 | AW3: =AV3-$H$25 -> 3.5554366 | AX3: =2^-AW3 -> 0.085056387 | AY3: =LOG(AX3,2) -> -3.5554366
